<mujoco model="box">
  <option timestep="0.01" integrator="RK4">
    <flag contact="disable" energy="enable"/>
  </option>

  <worldbody>
    <light name="light" pos="0 0 6"/>
    <camera name="fixed" pos="0 -4 1" zaxis="0 -1 0"/>
    <camera name="lookatcart" mode="targetbody" target="cart" pos="0 -2 2"/>
    <geom name="floor" pos="0 0 0" size="4 4 .2" type="plane"/>
    <body name="cart" pos="4 0 0.1">
      <geom name="cart" type="box" size="0.1 0.1 0.1" mass="1"/>
      <joint name='slider' type='slide' pos='0 0 0' axis='1 0 0' />
    </body>
  </worldbody>

  <actuator>
    <motor name="slide" joint="slider" gear="10" ctrllimited="true" ctrlrange="-1 1" />
  </actuator>
</mujoco>